<?xml version="1.0"?>
<robot name="rb1_robot" xmlns:xacro="http://ros.org/wiki/xacro">
  <xacro:include filename="$(find rb1_description)/urdf/rb1_description.gazebo.xacro"/>

  <!-- Define robot constants -->
  <xacro:property name="base_length" value="0.952"/>
  <xacro:property name="base_width" value="0.550"/>
  <xacro:property name="base_height" value="0.882"/>
  <xacro:property name="wheel_radius" value="0.373"/>
  <xacro:property name="wheel_width" value="0.085"/>
  <xacro:property name="back_wheel_radius" value="0.158"/>
  <xacro:property name="back_wheel_width" value="0.04"/>
  <xacro:property name="wheel_roll" value="0.1"/>
  <xacro:property name="wheel_ygap" value="0.0"/>
  <xacro:property name="wheel_zoff" value="0.02"/>
  <xacro:property name="wheel_xoff" value="0.0"/>


  <!-- Define some commonly used intertial properties  -->
  <xacro:macro name="box_inertia" params="m w h d">
    <inertial>
      <origin xyz="0 0 0" rpy="${pi/2} 0 ${pi/2}"/>      
      <mass value="${m}"/>
      <inertia ixx="${(m/12) * (h*h + d*d)}" ixy="0.0" ixz="0.0" iyy="${(m/12) * (w*w + d*d)}" iyz="0.0" izz="${(m/12) * (w*w + h*h)}"/>
    </inertial>
  </xacro:macro>

  <xacro:macro name="cylinder_inertia" params="m r h">
    <inertial>
      <origin xyz="0 0 0" rpy="${pi/2} 0 0" />      
      <mass value="${m}"/>
      <inertia ixx="${(m/12) * (3*r*r + h*h)}" ixy = "0" ixz = "0" iyy="${(m/12) * (3*r*r + h*h)}" iyz = "0" izz="${(m/2) * (r*r)}"/> 
    </inertial>
  </xacro:macro>

  <xacro:macro name="sphere_inertia" params="m r">
    <inertial>
      <mass value="${m}"/>
      <inertia ixx="${(2/5) * m * (r*r)}" ixy="0.0" ixz="0.0" iyy="${(2/5) * m * (r*r)}" iyz="0.0" izz="${(2/5) * m * (r*r)}"/>
    </inertial>
  </xacro:macro>

<link name="chassis_link">
        <visual>
            <origin xyz="1.04083e-17 0 0" rpy="0 0 ${pi/2}" />
            <geometry>
                <mesh filename="file://$(find rb1_description)/meshes/camera.stl" />
            </geometry>
            <material name="camera_material">
                <color rgba="0.647059 0.647059 0.647059 1.0" />
            </material>
        </visual>
        <collision>
            <origin xyz="1.04083e-17 0 0" rpy="0 0 ${pi/2}" />
            <geometry>
                <mesh filename="file://$(find rb1_description)/meshes/camera.stl" />
            </geometry>
            <material name="camera_material">
                <color rgba="0.647059 0.647059 0.647059 1.0" />
            </material>
        </collision>
        <visual>
            <origin xyz="0 0 0" rpy="0 0 ${pi/2}" />
            <geometry>
                <mesh filename="file://$(find rb1_description)/meshes/chassis.stl" />
            </geometry>
            <material name="chassis_material">
                <color rgba="0.917647 0.917647 0.917647 1.0" />
            </material>
        </visual>
        <collision>
            <origin xyz="0 0 0" rpy="0 0 ${pi/2}" />
            <geometry>
                <mesh filename="file://$(find rb1_description)/meshes/chassis.stl" />
            </geometry>
            <material name="chassis_material">
                <color rgba="0.917647 0.917647 0.917647 1.0" />
            </material>
        </collision>
        <inertial>
            <origin xyz="-3.7281e-05 0.104544 0.0323681" rpy="0 0 ${pi/2}" />
            <mass value="36.6716" />
            <inertia ixx="2.27344" ixy="1.91638e-05" ixz="-5.11576e-05" iyy="1.41294" iyz="0.0305872" izz="1.67957" />
        </inertial>
    </link>


    <link name="back_wheel_turn">
        <visual>
            <origin xyz="-0.15 0.0 0" rpy="0 0 ${pi/2}" />
            <geometry>
                <mesh filename="file://$(find rb1_description)/meshes/back_wheel_turn.stl" />
            </geometry>
            <material name="back_wheel_turn_material">
                <color rgba="0.537255 0.827451 0.0980392 1.0" />
            </material>
        </visual>
        <inertial>
            <origin xyz="-1.09595e-08 0.0291725 -0.0867154" rpy="0 0 ${pi/2}" />
            <mass value="1.21915" />
            <inertia ixx="0.00997145" ixy="2.90872e-11" ixz="1.90121e-10" iyy="0.00810055" iyz="0.00321231" izz="0.0043072" />
        </inertial>
    </link>

    <link name="back_wheel">
        <visual>
            <origin xyz="0 0 0" rpy="0 0 ${pi/2}" />
            <geometry>
                <mesh filename="file://$(find rb1_description)/meshes/back_wheel.stl" />
            </geometry>
            <material name="back_wheel_material">
                <color rgba="0.262745 0.282353 0.301961 1.0" />
            </material>
        </visual>
        <collision>
            <origin xyz="0 0 0" rpy="${pi/2} 0 0" />
            <geometry>
                <cylinder radius="${back_wheel_radius}" length="${back_wheel_width}"/>
            </geometry>
        </collision>
        <inertial>
            <origin xyz="0 0 0" rpy="0 0 ${pi/2}" />
            <mass value="1.36554" />
            <inertia ixx="0.0108958" ixy="-1.34816e-08" ixz="1.47366e-07" iyy="0.0212732" iyz="-1.33533e-07" izz="0.0108939" />
        </inertial>
    </link>

  <xacro:macro name="wheel" params="prefix x_reflect y_reflect">
    <link name="${prefix}_link">
        <visual>
            <origin xyz="0 0 0" rpy="0.0 0 ${pi/2}" />
            <geometry>
                <mesh filename="file://$(find rb1_description)/meshes/drive_wheel.stl" />
            </geometry>
            <material name="drive_wheel_material">
                <color rgba="0.34902 0.376471 0.4 1.0" />
            </material>
        </visual>
        <collision>
            <origin xyz="0 0 0" rpy="${pi/2} 0 0" />
            <geometry>
                <cylinder radius="${wheel_radius}" length="${wheel_width}"/>
            </geometry>
        </collision>
        <inertial>
            <origin xyz="1.47838e-08 1.65838e-14 -0.05438" rpy="0 0 0" />
            <mass value="2.30502" />
            <inertia ixx="0.110044" ixy="1.68377e-15" ixz="7.10622e-13" iyy="0.214728" iyz="-8.63501e-11" izz="0.109234" />
        </inertial>
    </link>

    <joint name="${prefix}_joint" type="continuous">
      <parent link="chassis_link"/>
      <child link="${prefix}_link"/>
      <origin xyz="0 ${y_reflect*(base_width/2+wheel_ygap)} ${wheel_zoff}" rpy="${y_reflect*wheel_roll} 0 0"/>
      <axis xyz="0 1 0"/>
    </joint>
  </xacro:macro>


  <xacro:wheel prefix="drivewhl_l" x_reflect="0" y_reflect="1" />
  <xacro:wheel prefix="drivewhl_r" x_reflect="0" y_reflect="-1" />

    <link name="base_link">
    <xacro:box_inertia m="0" w="0" d="0" h="0"/>
    </link>

    <joint name="base_link_joint" type="fixed">
        <origin xyz="0 0 0" rpy="0 0 0" />
        <parent link="base_link"/>
        <child link="chassis_link" />
    </joint>

    <joint name = "base_joint"  type = "continuous">
        <parent link="chassis_link"/>
        <child link="back_wheel_turn"/>
        <origin xyz="-0.68 0.0 -0.2" rpy="0 0 0" />
        <axis xyz="0 0 1" rpy="0 0 0" />
    </joint>

    <joint name="castor_wheel" type="continuous">
        <origin xyz="-0.15 0 0" rpy="0 0 0" />
        <parent link="back_wheel_turn" />
        <child link="back_wheel" />
        <axis xyz="0 1 0" />
    </joint>


<!--  _______________________________________________________  -->



    <joint name="imu_joint" type="fixed">
        <parent link="base_link"/>
        <child link="imu_link"/>
        <origin xyz="-0.032 0 0.068" rpy="0 0 0"/>
    </joint>

    <link name="imu_link"/>


    <joint name="scan_joint" type="fixed">
        <parent link="base_link"/>
        <child link="base_scan"/>
        <origin xyz="-0.032 0 1" rpy="0 0 0"/>
    </joint>


    <link name="base_scan">
    <visual>
      <origin xyz="0 0 0.0" rpy="0 0 0"/>
      <geometry>
        <mesh filename="package://turtlebot3_description/meshes/sensors/lds.stl" scale="0.001 0.001 0.001"/>
      </geometry>
      <material name="dark"/>
    </visual>

    <collision>
      <origin xyz="0.015 0 -0.0065" rpy="0 0 0"/>
      <geometry>
        <cylinder length="0.0315" radius="0.055"/>
      </geometry>
    </collision>

    <inertial>
      <mass value="0.114" />
      <origin xyz="0 0 0" />
      <inertia ixx="0.001" ixy="0.0" ixz="0.0"
               iyy="0.001" iyz="0.0"
               izz="0.001" />
    </inertial>
  </link>






    
</robot>
